<mujoco>
  <visual>
    <global offwidth="1980" offheight="1080"/>
  </visual>

  <asset>
    <texture name="grid" type="2d" builtin="checker" width="512" height="512" rgb1=".1 .2 .3" rgb2=".2 .3 .4"/>
    <material name="grid" texture="grid" texrepeat="1 1" texuniform="true" reflectance=".2"/>
  </asset>

  <worldbody>  <! body idx: 0 />
    <light name="top" pos="0 0 3"/>
    <body name="link1" pos="0 0 .01">  <! body idx: 1 />
      <joint name="tx" type="slide" axis="1 0 0"/>
      <inertial pos="0 0 0" mass="1" diaginertia=".00001 .00001 .00001"/>
      <body name="link2">  <! body idx: 2 />
        <joint name="ty" type="slide" axis="0 1 0"/>
        <inertial pos="0 0 0" mass="1" diaginertia=".00001 .00001 .00001"/>
        <body name="link3">  <! body idx: 3 />
          <joint name="tz" type="slide" axis="0 0 1"/>
          <inertial pos="0 0 0" mass="1" diaginertia=".00001 .00001 .00001"/>
          <body name="link4">  <! body idx: 4 />
            <joint name="rx" type="hinge" axis="1 0 0"/>
            <inertial pos="0 0 0" mass="1" diaginertia=".00001 .00001 .00001"/>
            <body name="link5">  <! body idx: 5 />
              <joint name="ry" type="hinge" axis="0 1 0"/>
              <inertial pos="0 0 0" mass="1" diaginertia=".00001 .00001 .00001"/>
              <body name="object">  <! body idx: 6 />
                <joint name="rz" type="hinge" axis="0 0 1"/>
                <site name="ft_sen"/>
                <geom name="red_plastic_cuboid" type="box" density="1060" size=".1 .2 .3" rgba="1 0 0 1"/>
                <!geom name="red_plastic_cudoid" type="box" density="1060" size=".1 .2 .15" pos="0 0 .15" rgba="0 1 0 1"/>
                <!geom name="beige_marble_cuboid" type="box" density="2690" size=".1 .2 .15" pos="0 0 -.15" rgba="0 0 1 1"/>
                <camera name="tracking" mode="track" pos="0 0 1"/>
              </body>
            </body>
          </body>
        </body>
      </body>
    </body>
  </worldbody>

  <actuator>
    <motor name="mtr_tx" joint="tx"/>
    <motor name="mtr_ty" joint="ty"/>
    <motor name="mtr_tz" joint="tz"/>
    <motor name="mtr_rx" joint="rx"/>
    <motor name="mtr_ry" joint="ry"/>
    <motor name="mtr_rz" joint="rz"/>
  </actuator>

  <sensor>
    <actuatorfrc name="frc_tx" actuator="mtr_tx"/>  <! sensordata group idx: 0 />
    <actuatorfrc name="frc_ty" actuator="mtr_ty"/>
    <actuatorfrc name="frc_tz" actuator="mtr_tz"/>
    <actuatorfrc name="frc_rx" actuator="mtr_rx"/>
    <actuatorfrc name="frc_ry" actuator="mtr_ry"/>
    <actuatorfrc name="frc_rz" actuator="mtr_rz"/>
    <force name="frc" site="ft_sen"/>  <! sensordata group idx: 1 />
    <torque name="trq" site="ft_sen"/>
    <framelinvel name="linvel_x_obj" objtype="body" objname="object"/>  <! sensordata group idx: 2 />
    <frameangvel name="angvel_x_obj" objtype="body" objname="object"/>
    <framelinacc name="linacc_x_obj" objtype="body" objname="object"/>  <! sensordata group idx: 3 />
    <frameangacc name="angacc_x_obj" objtype="body" objname="object"/>
  </sensor>

  <keyframe>
    <key name="init_pose" qpos="1 1 1 0 0 0"/>
  </keyframe>
</mujoco>
